Workbook

Sheet EF
A1: PANGEA NATURAL PRODUCTS S.A.S.
A2: NIT. 901.196.219-5
A3: ESTADO DE SITUACIÓN FINANCIERA
A4: (Expresados en pesos colombianos)
A6: Período terminado a
B7: ACTIVO | C7: Nota | D7: MARZO de 2026 | E7: % | F7: PERIODO ANTERIOR TEST | G7: % | H7: Variación | I7: % | J7: FILTRO
B8: CORRIENTE | J8: TRUE
A9: 11 11C | B9: Efectivo y Equivalentes al Efectivo | C9: 1 | D9: =SUM(D10,D213,D220,D273,D3813,D3816,D6895) | E9: =IF($D$7125=0,0,D9/ABS($D$7125)) | F9: =SUM(F10,F213,F220,F273,F3813,F3816,F6895) | G9: =IF($F$7125=0,0,F9/ABS($F$7125)) | H9: =D9-F9 | I9: =IF(F9=0,0,H9/ABS(F9)) | J9: TRUE
A10: 1105050101 | B10: Caja Menor | D10: =SUM(D11:D212) | E10: =IF($D$7125=0,0,D10/ABS($D$7125)) | F10: =SUM(F11:F212) | G10: =IF($F$7125=0,0,F10/ABS($F$7125)) | H10: =D10-F10 | I10: =IF(F10=0,0,H10/ABS(F10)) | J10: TRUE
B11: Abhay Organica | D11: 199998 | E11: =IF($D$7125=0,0,D11/ABS($D$7125)) | F11: 199998 | G11: =IF($F$7125=0,0,F11/ABS($F$7125)) | H11: =D11-F11 | I11: =IF(F11=0,0,H11/ABS(F11)) | J11: TRUE
B12: BIOMARKET | D12: 153333 | E12: =IF($D$7125=0,0,D12/ABS($D$7125)) | F12: 153333 | G12: =IF($F$7125=0,0,F12/ABS($F$7125)) | H12: =D12-F12 | I12: =IF(F12=0,0,H12/ABS(F12)) | J12: TRUE
B13: BOLSAS Y PLASTICOS LA 15 LTDA | D13: -58100 | E13: =IF($D$7125=0,0,D13/ABS($D$7125)) | F13: -58100 | G13: =IF($F$7125=0,0,F13/ABS($F$7125)) | H13: =D13-F13 | I13: =IF(F13=0,0,H13/ABS(F13)) | J13: TRUE
B14: CAMARA DE COMERCIO DE CALI | D14: -6200 | E14: =IF($D$7125=0,0,D14/ABS($D$7125)) | F14: -6200 | G14: =IF($F$7125=0,0,F14/ABS($F$7125)) | H14: =D14-F14 | I14: =IF(F14=0,0,H14/ABS(F14)) | J14: TRUE
B15: DENOMINACION ORIGEN SAS | D15: 347996 | E15: =IF($D$7125=0,0,D15/ABS($D$7125)) | F15: 347996 | G15: =IF($F$7125=0,0,F15/ABS($F$7125)) | H15: =D15-F15 | I15: =IF(F15=0,0,H15/ABS(F15)) | J15: TRUE
B16: Fisioactivity | D16: 413917 | E16: =IF($D$7125=0,0,D16/ABS($D$7125)) | F16: 413917 | G16: =IF($F$7125=0,0,F16/ABS($F$7125)) | H16: =D16-F16 | I16: =IF(F16=0,0,H16/ABS(F16)) | J16: TRUE
B17: HEALTHY ORGANIC MARKET | D17: 419999 | E17: =IF($D$7125=0,0,D17/ABS($D$7125)) | F17: 419999 | G17: =IF($F$7125=0,0,F17/ABS($F$7125)) | H17: =D17-F17 | I17: =IF(F17=0,0,H17/ABS(F17)) | J17: TRUE
B18: KOBA COLOMBIA SAS | D18: -91740 | E18: =IF($D$7125=0,0,D18/ABS($D$7125)) | F18: -91740 | G18: =IF($F$7125=0,0,F18/ABS($F$7125)) | H18: =D18-F18 | I18: =IF(F18=0,0,H18/ABS(F18)) | J18: TRUE
B19: MANCHOLA ASOCIADOS LTDA | D19: 60000 | E19: =IF($D$7125=0,0,D19/ABS($D$7125)) | F19: 60000 | G19: =IF($F$7125=0,0,F19/ABS($F$7125)) | H19: =D19-F19 | I19: =IF(F19=0,0,H19/ABS(F19)) | J19: TRUE
B20: Naturalfit | D20: 183333 | E20: =IF($D$7125=0,0,D20/ABS($D$7125)) | F20: 183333 | G20: =IF($F$7125=0,0,F20/ABS($F$7125)) | H20: =D20-F20 | I20: =IF(F20=0,0,H20/ABS(F20)) | J20: TRUE
B21: PANGEA NATURAL PRODUCTS S.A.S. | D21: -31137534 | E21: =IF($D$7125=0,0,D21/ABS($D$7125)) | F21: -31137534 | G21: =IF($F$7125=0,0,F21/ABS($F$7125)) | H21: =D21-F21 | I21: =IF(F21=0,0,H21/ABS(F21)) | J21: TRUE
B22: SUPERFUDS SAS | D22: 26001 | E22: =IF($D$7125=0,0,D22/ABS($D$7125)) | F22: 26001 | G22: =IF($F$7125=0,0,F22/ABS($F$7125)) | H22: =D22-F22 | I22: =IF(F22=0,0,H22/ABS(F22)) | J22: TRUE
... B212: isabela Arias | D212: 215000 | E212: =IF($D$7125=0,0,D212/ABS($D$7125)) | F212: 215000 | G212: =IF($F$7125=0,0,F212/ABS($F$7125)) | H212: =D212-F212 | I212: =IF(F212=0,0,H212/ABS(F212)) | J212: TRUE
A213: 11051001 | B213: Cajas menores | D213: =SUM(D214:D219) | E213: =IF($D$7125=0,0,D213/ABS($D$7125)) | F213: =SUM(F214:F219) | G213: =IF($F$7125=0,0,F213/ABS($F$7125)) | H213: =D213-F213 | I213: =IF(F213=0,0,H213/ABS(F213)) | J213: TRUE
B214: PANGEA NATURAL PRODUCTS S.A.S. | D214: 248059.44 | E214: =IF($D$7125=0,0,D214/ABS($D$7125)) | F214: 248059.44 | G214: =IF($F$7125=0,0,F214/ABS($F$7125)) | H214: =D214-F214 | I214: =IF(F214=0,0,H214/ABS(F214)) | J214: TRUE
B215: AEROVIAS DEL CONTINENTE AMERICANO S.A. | D215: -708459.44 | E215: =IF($D$7125=0,0,D215/ABS($D$7125)) | F215: -708459.44 | G215: =IF($F$7125=0,0,F215/ABS($F$7125)) | H215: =D215-F215 | I215: =IF(F215=0,0,H215/ABS(F215)) | J215: TRUE
B216: FRISBY S.A. | D216: -23300 | E216: =IF($D$7125=0,0,D216/ABS($D$7125)) | F216: -23300 | G216: =IF($F$7125=0,0,F216/ABS($F$7125)) | H216: =D216-F216 | I216: =IF(F216=0,0,H216/ABS(F216)) | J216: TRUE
B217: MUNICIPIO DE SANTIAGO DE CALI | D217: -253000 | E217: =IF($D$7125=0,0,D217/ABS($D$7125)) | F217: -253000 | G217: =IF($F$7125=0,0,F217/ABS($F$7125)) | H217: =D217-F217 | I217: =IF(F217=0,0,H217/ABS(F217)) | J217: TRUE
B218: OLGA BARBOSA DE HURTADO | D218: -100000 | E218: =IF($D$7125=0,0,D218/ABS($D$7125)) | F218: -100000 | G218: =IF($F$7125=0,0,F218/ABS($F$7125)) | H218: =D218-F218 | I218: =IF(F218=0,0,H218/ABS(F218)) | J218: TRUE
B219: Sebastian Mendoza Castaño | D219: 1436700 | E219: =IF($D$7125=0,0,D219/ABS($D$7125)) | F219: 1436700 | G219: =IF($F$7125=0,0,F219/ABS($F$7125)) | H219: =D219-F219 | I219: =IF(F219=0,0,H219/ABS(F219)) | J219: TRUE
A220: 11100503 | B220: Cuenta Cte. Banco de Bogota | D220: =SUM(D221:D272) | E220: =IF($D$7125=0,0,D220/ABS($D$7125)) | F220: =SUM(F221:F272) | G220: =IF($F$7125=0,0,F220/ABS($F$7125)) | H220: =D220-F220 | I220: =IF(F220=0,0,H220/ABS(F220)) | J220: TRUE
B221: ANILLANDO CALI LTDA | D221: -45000 | E221: =IF($D$7125=0,0,D221/ABS($D$7125)) | F221: -45000 | G221: =IF($F$7125=0,0,F221/ABS($F$7125)) | H221: =D221-F221 | I221: =IF(F221=0,0,H221/ABS(F221)) | J221: TRUE
B222: DOCUPRINT SAS | D222: -10350 | E222: =IF($D$7125=0,0,D222/ABS($D$7125)) | F222: -10350 | G222: =IF($F$7125=0,0,F222/ABS($F$7125)) | H222: =D222-F222 | I222: =IF(F222=0,0,H222/ABS(F222)) | J222: TRUE
B223: ESCARRIA PRINTS DIGITAL SAS | D223: -590240 | E223: =IF($D$7125=0,0,D223/ABS($D$7125)) | F223: -590240 | G223: =IF($F$7125=0,0,F223/ABS($F$7125)) | H223: =D223-F223 | I223: =IF(F223=0,0,H223/ABS(F223)) | J223: TRUE
B224: GERMAN DE JESUS CARDONA | D224: 270302 | E224: =IF($D$7125=0,0,D224/ABS($D$7125)) | F224: 270302 | G224: =IF($F$7125=0,0,F224/ABS($F$7125)) | H224: =D224-F224 | I224: =IF(F224=0,0,H224/ABS(F224)) | J224: TRUE
B225: INALI ZONA FRANCA SAS | D225: -464100 | E225: =IF($D$7125=0,0,D225/ABS($D$7125)) | F225: -464100 | G225: =IF($F$7125=0,0,F225/ABS($F$7125)) | H225: =D225-F225 | I225: =IF(F225=0,0,H225/ABS(F225)) | J225: TRUE
B226: INSTITUTO NACIONAL DE VIGILANCIA DE MEDICAMENTOS Y ALIMENTOS - INVIMA | D226: -2578099 | E226: =IF($D$7125=0,0,D226/ABS($D$7125)) | F226: -2578099 | G226: =IF($F$7125=0,0,F226/ABS($F$7125)) | H226: =D226-F226 | I226: =IF(F226=0,0,H226/ABS(F226)) | J226: TRUE
B227: MANCHOLA ASOCIADOS LTDA | D227: -2675000 | E227: =IF($D$7125=0,0,D227/ABS($D$7125)) | F227: -2675000 | G227: =IF($F$7125=0,0,F227/ABS($F$7125)) | H227: =D227-F227 | I227: =IF(F227=0,0,H227/ABS(F227)) | J227: TRUE
B228: MONCIEL SAS | D228: 1073334 | E228: =IF($D$7125=0,0,D228/ABS($D$7125)) | F228: 1073334 | G228: =IF($F$7125=0,0,F228/ABS($F$7125)) | H228: =D228-F228 | I228: =IF(F228=0,0,H228/ABS(F228)) | J228: TRUE
B229: MULTICARTON S.A.S. | D229: -477359 | E229: =IF($D$7125=0,0,D229/ABS($D$7125)) | F229: -477359 | G229: =IF($F$7125=0,0,F229/ABS($F$7125)) | H229: =D229-F229 | I229: =IF(F229=0,0,H229/ABS(F229)) | J229: TRUE
B230: PANGEA NATURAL PRODUCTS S.A.S. | D230: 22663323 | E230: =IF($D$7125=0,0,D230/ABS($D$7125)) | F230: 22663323 | G230: =IF($F$7125=0,0,F230/ABS($F$7125)) | H230: =D230-F230 | I230: =IF(F230=0,0,H230/ABS(F230)) | J230: TRUE
...

Sheet ER
A1: PANGEA NATURAL PRODUCTS S.A.S.
A2: NIT. 901.196.219-5
A3: ESTADO DE RESULTADO INTEGRAL
A4: (Expresados en pesos colombianos)
A6: Período comprendido entre
A7: 01 de Enero y al fin del mes de : MARZO de 2026
A9: Actividades Ordinarias | C9: Nota | D9: MARZO de 2026 | E9: % | F9: PERIODO ANTERIOR TEST | G9: % | H9: VARIACIÓN | I9: % | J9: FILTRO
B10: Venta de producto y prestación de servicios | C10: 14 | D10: =SUM(D11,D3174,D3176,D3238,D3244,D3246,D3331) | E10: =IF($D$10=0,0,D10/ABS($D$10)) | F10: =SUM(F11,F3174,F3176,F3238,F3244,F3246,F3331) | G10: =IF($F$10=0,0,F10/ABS($F$10)) | H10: =D10-F10 | I10: =IF(F10=0,0,H10/ABS(F10)) | J10: TRUE
B11: 41350101 - Comercio al por mayor y al detal | D11: =SUM(D12:D3173) | E11: =IF($D$10=0,0,D11/ABS($D$10)) | F11: =SUM(F12:F3173) | G11: =IF($F$10=0,0,F11/ABS($F$10)) | H11: =D11-F11 | I11: =IF(F11=0,0,H11/ABS(F11)) | J11: TRUE
B12: PANGEA NATURAL PRODUCTS S.A.S. | D12: 0 | E12: =IF($D$10=0,0,D12/ABS($D$10)) | F12: 0 | G12: =IF($F$10=0,0,F12/ABS($F$10)) | H12: =D12-F12 | I12: =IF(F12=0,0,H12/ABS(F12)) | J12: TRUE
B13: ACM PHARMA S.A.S | D13: 0 | E13: =IF($D$10=0,0,D13/ABS($D$10)) | F13: 0 | G13: =IF($F$10=0,0,F13/ABS($F$10)) | H13: =D13-F13 | I13: =IF(F13=0,0,H13/ABS(F13)) | J13: TRUE
B14: ADWELLCH SAS | D14: 3644026.9 | E14: =IF($D$10=0,0,D14/ABS($D$10)) | F14: 3644026.9 | G14: =IF($F$10=0,0,F14/ABS($F$10)) | H14: =D14-F14 | I14: =IF(F14=0,0,H14/ABS(F14)) | J14: TRUE
B15: ALIMENTOS SOSTENIBLES SAS | D15: 0 | E15: =IF($D$10=0,0,D15/ABS($D$10)) | F15: 0 | G15: =IF($F$10=0,0,F15/ABS($F$10)) | H15: =D15-F15 | I15: =IF(F15=0,0,H15/ABS(F15)) | J15: TRUE
B16: ARTEMISA S.A.S BIC | D16: 22044504 | E16: =IF($D$10=0,0,D16/ABS($D$10)) | F16: 22044504 | G16: =IF($F$10=0,0,F16/ABS($F$10)) | H16: =D16-F16 | I16: =IF(F16=0,0,H16/ABS(F16)) | J16: TRUE
B17: Alejandra Muñoz Fernández | D17: 0 | E17: =IF($D$10=0,0,D17/ABS($D$10)) | F17: 0 | G17: =IF($F$10=0,0,F17/ABS($F$10)) | H17: =D17-F17 | I17: =IF(F17=0,0,H17/ABS(F17)) | J17: TRUE
B18: Alfonso Narvaez | D18: 0 | E18: =IF($D$10=0,0,D18/ABS($D$10)) | F18: 0 | G18: =IF($F$10=0,0,F18/ABS($F$10)) | H18: =D18-F18 | I18: =IF(F18=0,0,H18/ABS(F18)) | J18: TRUE
B19: Amelia Bueno | D19: 0 | E19: =IF($D$10=0,0,D19/ABS($D$10)) | F19: 0 | G19: =IF($F$10=0,0,F19/ABS($F$10)) | H19: =D19-F19 | I19: =IF(F19=0,0,H19/ABS(F19)) | J19: TRUE
B20: Ana Maria Rugeles | D20: 0 | E20: =IF($D$10=0,0,D20/ABS($D$10)) | F20: 0 | G20: =IF($F$10=0,0,F20/ABS($F$10)) | H20: =D20-F20 | I20: =IF(F20=0,0,H20/ABS(F20)) | J20: TRUE
B21: Andrea Marcela Martínez Pulido | D21: 0 | E21: =IF($D$10=0,0,D21/ABS($D$10)) | F21: 0 | G21: =IF($F$10=0,0,F21/ABS($F$10)) | H21: =D21-F21 | I21: =IF(F21=0,0,H21/ABS(F21)) | J21: TRUE
B22: Andrea Restrepo | D22: 0 | E22: =IF($D$10=0,0,D22/ABS($D$10)) | F22: 0 | G22: =IF($F$10=0,0,F22/ABS($F$10)) | H22: =D22-F22 | I22: =IF(F22=0,0,H22/ABS(F22)) | J22: TRUE
B23: Artha Group SAS | D23: 0 | E23: =IF($D$10=0,0,D23/ABS($D$10)) | F23: 0 | G23: =IF($F$10=0,0,F23/ABS($F$10)) | H23: =D23-F23 | I23: =IF(F23=0,0,H23/ABS(F23)) | J23: TRUE
... B3173: Yorleidy Sarrazola | D3173: 0 | E3173: =IF($D$10=0,0,D3173/ABS($D$10)) | F3173: 0 | G3173: =IF($F$10=0,0,F3173/ABS($F$10)) | H3173: =D3173-F3173 | I3173: =IF(F3173=0,0,H3173/ABS(F3173)) | J3173: TRUE
B3174: 41350102 - Descuentos | D3174: =SUM(D3175:D3175) | E3174: =IF($D$10=0,0,D3174/ABS($D$10)) | F3174: =SUM(F3175:F3175) | G3174: =IF($F$10=0,0,F3174/ABS($F$10)) | H3174: =D3174-F3174 | I3174: =IF(F3174=0,0,H3174/ABS(F3174)) | J3174: TRUE
B3175: ONLINE Paula Andrea Ramirez Forero | D3175: 0 | E3175: =IF($D$10=0,0,D3175/ABS($D$10)) | F3175: 0 | G3175: =IF($F$10=0,0,F3175/ABS($F$10)) | H3175: =D3175-F3175 | I3175: =IF(F3175=0,0,H3175/ABS(F3175)) | J3175: TRUE
B3176: 41750501 - Devolución en ventas | D3176: =SUM(D3177:D3237) | E3176: =IF($D$10=0,0,D3176/ABS($D$10)) | F3176: =SUM(F3177:F3237) | G3176: =IF($F$10=0,0,F3176/ABS($F$10)) | H3176: =D3176-F3176 | I3176: =IF(F3176=0,0,H3176/ABS(F3176)) | J3176: TRUE
B3177: ACM PHARMA S.A.S | D3177: 0 | E3177: =IF($D$10=0,0,D3177/ABS($D$10)) | F3177: 0 | G3177: =IF($F$10=0,0,F3177/ABS($F$10)) | H3177: =D3177-F3177 | I3177: =IF(F3177=0,0,H3177/ABS(F3177)) | J3177: TRUE
B3178: ADWELLCH SAS | D3178: -761643.54 | E3178: =IF($D$10=0,0,D3178/ABS($D$10)) | F3178: -761643.54 | G3178: =IF($F$10=0,0,F3178/ABS($F$10)) | H3178: =D3178-F3178 | I3178: =IF(F3178=0,0,H3178/ABS(F3178)) | J3178: TRUE
B3179: ARTEMISA S.A.S BIC | D3179: -1055505.9 | E3179: =IF($D$10=0,0,D3179/ABS($D$10)) | F3179: -1055505.9 | G3179: =IF($F$10=0,0,F3179/ABS($F$10)) | H3179: =D3179-F3179 | I3179: =IF(F3179=0,0,H3179/ABS(F3179)) | J3179: TRUE
B3180: AUDIFARMA S.A. | D3180: 0 | E3180: =IF($D$10=0,0,D3180/ABS($D$10)) | F3180: 0 | G3180: =IF($F$10=0,0,F3180/ABS($F$10)) | H3180: =D3180-F3180 | I3180: =IF(F3180=0,0,H3180/ABS(F3180)) | J3180: TRUE
B3181: CAJA COLOMBIANA DE SUBSIDIO FAMILIAR COLSUBSIDIO | D3181: 0 | E3181: =IF($D$10=0,0,D3181/ABS($D$10)) | F3181: 0 | G3181: =IF($F$10=0,0,F3181/ABS($F$10)) | H3181: =D3181-F3181 | I3181: =IF(F3181=0,0,H3181/ABS(F3181)) | J3181: TRUE
B3182: COCOFIT MERCADO SALUDABLE S.A.S. | D3182: 0 | E3182: =IF($D$10=0,0,D3182/ABS($D$10)) | F3182: 0 | G3182: =IF($F$10=0,0,F3182/ABS($F$10)) | H3182: =D3182-F3182 | I3182: =IF(F3182=0,0,H3182/ABS(F3182)) | J3182: TRUE
B3183: Clavijo Martinez Inversiones cia s en c | D3183: 0 | E3183: =IF($D$10=0,0,D3183/ABS($D$10)) | F3183: 0 | G3183: =IF($F$10=0,0,F3183/ABS($F$10)) | H3183: =D3183-F3183 | I3183: =IF(F3183=0,0,H3183/ABS(F3183)) | J3183: TRUE
B3184: Consumidor Final | D3184: -841092.43 | E3184: =IF($D$10=0,0,D3184/ABS($D$10)) | F3184: -841092.43 | G3184: =IF($F$10=0,0,F3184/ABS($F$10)) | H3184: =D3184-F3184 | I3184: =IF(F3184=0,0,H3184/ABS(F3184)) | J3184: TRUE
B3185: DANIELA ARBELAEZ | D3185: 0 | E3185: =IF($D$10=0,0,D3185/ABS($D$10)) | F3185: 0 | G3185: =IF($F$10=0,0,F3185/ABS($F$10)) | H3185: =D3185-F3185 | I3185: =IF(F3185=0,0,H3185/ABS(F3185)) | J3185: TRUE
B3186: DISTRIBUIDORA PASTEUR | D3186: -25953413 | E3186: =IF($D$10=0,0,D3186/ABS($D$10)) | F3186: -25953413 | G3186: =IF($F$10=0,0,F3186/ABS($F$10)) | H3186: =D3186-F3186 | I3186: =IF(F3186=0,0,H3186/ABS(F3186)) | J3186: TRUE
B3187: DISTRIBUIDORA SALUD NATURAL S.A.S | D3187: 0 | E3187: =IF($D$10=0,0,D3187/ABS($D$10)) | F3187: 0 | G3187: =IF($F$10=0,0,F3187/ABS($F$10)) | H3187: =D3187-F3187 | I3187: =IF(F3187=0,0,H3187/ABS(F3187)) | J3187: TRUE
B3188: Droguerías Juliao S.A Mariela Ester Juliao del Río | D3188: -2575149.9 | E3188: =IF($D$10=0,0,D3188/ABS($D$10)) | F3188: -2575149.9 | G3188: =IF($F$10=0,0,F3188/ABS($F$10)) | H3188: =D3188-F3188 | I3188: =IF(F3188=0,0,H3188/ABS(F3188)) | J3188: TRUE
... B3237: VITAINTEGRAL SAS | D3237: 0 | E3237: =IF($D$10=0,0,D3237/ABS($D$10)) | F3237: 0 | G3237: =IF($F$10=0,0,F3237/ABS($F$10)) | H3237: =D3237-F3237 | I3237: =IF(F3237=0,0,H3237/ABS(F3237)) | J3237: TRUE
B3238: 41750502 - Devolución en servicios | D3238: =SUM(D3239:D3243) | E3238: =IF($D$10=0,0,D3238/ABS($D$10)) | F3238: =SUM(F3239:F3243) | G3238: =IF($F$10=0,0,F3238/ABS($F$10)) | H3238: =D3238-F3238 | I3238: =IF(F3238=0,0,H3238/ABS(F3238)) | J3238: TRUE
B3239: ARTEMISA S.A.S BIC | D3239: 0 | E3239: =IF($D$10=0,0,D3239/ABS($D$10)) | F3239: 0 | G3239: =IF($F$10=0,0,F3239/ABS($F$10)) | H3239: =D3239-F3239 | I3239: =IF(F3239=0,0,H3239/ABS(F3239)) | J3239: TRUE
...

Sheet Notas
A1: PANGEA NATURAL PRODUCTS S.A.S.
A2: NIT. 901.196.219-5
A3: NOTAS A LOS ESTADOS FINANCIEROS
A4: (Expresados en pesos colombianos) — MARZO de 2026
A6: NOTA 1 Efectivo y Equivalentes al Efectivo
A7: CTA | B7: Cuenta / Tercero | C7: MARZO de 2026 | D7: PERIODO ANTERIOR TEST | E7: Variación | F7: % Variación
A8: 1105050101 | B8: Caja Menor | C8: =SUM(C9:C210) | D8: =SUM(D9:D210) | E8: =C8-D8 | F8: =IF(D8=0,0,E8/ABS(D8))
B9: ALIMENTOS SOSTENIBLES SAS | C9: 83000 | D9: 83000 | E9: =C9-D9 | F9: =IF(D9=0,0,E9/ABS(D9))
B10: ALVARO SILVA RAMOS | C10: -18000 | D10: -18000 | E10: =C10-D10 | F10: =IF(D10=0,0,E10/ABS(D10))
B11: AUDIFARMA S.A. | C11: -515375 | D11: -515375 | E11: =C11-D11 | F11: =IF(D11=0,0,E11/ABS(D11))
B12: Abhay Organica | C12: 199998 | D12: 199998 | E12: =C12-D12 | F12: =IF(D12=0,0,E12/ABS(D12))
B13: Adriana Castrillon | C13: 460000 | D13: 460000 | E13: =C13-D13 | F13: =IF(D13=0,0,E13/ABS(D13))
B14: Adriana Jaramillo | C14: 50001 | D14: 50001 | E14: =C14-D14 | F14: =IF(D14=0,0,E14/ABS(D14))
B15: Adriana Vega | C15: 180000 | D15: 180000 | E15: =C15-D15 | F15: =IF(D15=0,0,E15/ABS(D15))
B16: Alejandra Ortiz | C16: 30000 | D16: 30000 | E16: =C16-D16 | F16: =IF(D16=0,0,E16/ABS(D16))
B17: Alfonso Narvaez | C17: 650000 | D17: 650000 | E17: =C17-D17 | F17: =IF(D17=0,0,E17/ABS(D17))
B18: Alfredo Cienfuegos | C18: 210000 | D18: 210000 | E18: =C18-D18 | F18: =IF(D18=0,0,E18/ABS(D18))
B19: Alfredo Otero | C19: 70000 | D19: 70000 | E19: =C19-D19 | F19: =IF(D19=0,0,E19/ABS(D19))
B20: Alicia Cliente | C20: 570000 | D20: 570000 | E20: =C20-D20 | F20: =IF(D20=0,0,E20/ABS(D20))
... B210: isabela Arias | C210: 215000 | D210: 215000 | E210: =C210-D210 | F210: =IF(D210=0,0,E210/ABS(D210))
A211: 11051001 | B211: Cajas menores | C211: =SUM(C212:C217) | D211: =SUM(D212:D217) | E211: =C211-D211 | F211: =IF(D211=0,0,E211/ABS(D211))
B212: AEROVIAS DEL CONTINENTE AMERICANO S.A. | C212: -708459.44 | D212: -708459.44 | E212: =C212-D212 | F212: =IF(D212=0,0,E212/ABS(D212))
B213: FRISBY S.A. | C213: -23300 | D213: -23300 | E213: =C213-D213 | F213: =IF(D213=0,0,E213/ABS(D213))
B214: MUNICIPIO DE SANTIAGO DE CALI | C214: -253000 | D214: -253000 | E214: =C214-D214 | F214: =IF(D214=0,0,E214/ABS(D214))
B215: OLGA BARBOSA DE HURTADO | C215: -100000 | D215: -100000 | E215: =C215-D215 | F215: =IF(D215=0,0,E215/ABS(D215))
B216: PANGEA NATURAL PRODUCTS S.A.S. | C216: 248059.44 | D216: 248059.44 | E216: =C216-D216 | F216: =IF(D216=0,0,E216/ABS(D216))
B217: Sebastian Mendoza Castaño | C217: 1436700 | D217: 1436700 | E217: =C217-D217 | F217: =IF(D217=0,0,E217/ABS(D217))
A218: 11100503 | B218: Cuenta Cte. Banco de Bogota | C218: =SUM(C219:C270) | D218: =SUM(D219:D270) | E218: =C218-D218 | F218: =IF(D218=0,0,E218/ABS(D218))
B219: 900546298 | C219: -67000 | D219: -67000 | E219: =C219-D219 | F219: =IF(D219=0,0,E219/ABS(D219))
B220: ALIMENTOS SOSTENIBLES SAS | C220: 2576073 | D220: 2576073 | E220: =C220-D220 | F220: =IF(D220=0,0,E220/ABS(D220))
B221: ALMACENES LA 14 S.A. | C221: -132129 | D221: -132129 | E221: =C221-D221 | F221: =IF(D221=0,0,E221/ABS(D221))
B222: ANDRES FELIPE SANTACOLOMA | C222: -491370 | D222: -491370 | E222: =C222-D222 | F222: =IF(D222=0,0,E222/ABS(D222))
B223: ANILLANDO CALI LTDA | C223: -45000 | D223: -45000 | E223: =C223-D223 | F223: =IF(D223=0,0,E223/ABS(D223))
B224: Administradora de Fondos de Pensiones y Cesantía Protección S.A. | C224: -496070 | D224: -496070 | E224: =C224-D224 | F224: =IF(D224=0,0,E224/ABS(D224))
B225: Alejandro Giraldo Mejia | C225: -280020 | D225: -280020 | E225: =C225-D225 | F225: =IF(D225=0,0,E225/ABS(D225))
B226: Banco de bogotá | C226: 12963977 | D226: 12963977 | E226: =C226-D226 | F226: =IF(D226=0,0,E226/ABS(D226))
B227: CAMILO ANDRES TINJACA VILLAMIL | C227: -120000 | D227: -120000 | E227: =C227-D227 | F227: =IF(D227=0,0,E227/ABS(D227))
B228: CAROLINA GALEANO GARCIA | C228: -2879326 | D228: -2879326 | E228: =C228-D228 | F228: =IF(D228=0,0,E228/ABS(D228))
B229: CLAUDIA ARACELY TORRES RODRIGUEZ | C229: -220000 | D229: -220000 | E229: =C229-D229 | F229: =IF(D229=0,0,E229/ABS(D229))
B230: DIAN | C230: -2039000 | D230: -2039000 | E230: =C230-D230 | F230: =IF(D230=0,0,E230/ABS(D230))
...

Sheet Graficas
A1: PANGEA NATURAL PRODUCTS S.A.S.
A2: GRÁFICAS DE COMPOSICIÓN FINANCIERA
A5: Concepto | B5: Valor | F5: Concepto | G5: Valor | J5: Concepto | K5: Valor
A6: Efectivo y Equivalentes al Efectivo | B6: =ABS('EF'!D9) | F6: Obligaciones financieras | G6: =ABS('EF'!D7128) | J6: Ingresos | K6: =ABS('ER'!D10)
A7: Deudores comerciales y otras cuentas por cobrar | B7: =ABS('EF'!D6898) | F7: Cuentas comerciales por pagar y otras cuentas por pagar | G7: =ABS('EF'!D7195) | J7: Gastos Admin | K7: =ABS('ER'!D4669)
A8: Inventarios | B8: =ABS('EF'!D7093) | F8: Impuestos corrientes por pagar | G8: =ABS('EF'!D7717) | J8: Gastos Venta | K8: =ABS('ER'!D4747)
A9: Propiedades, Planta y Equipo | B9: =ABS('EF'!D7104) | F9: Obligaciones laborales | G9: =ABS('EF'!D14094) | J9: Costo Ventas | K9: =ABS('ER'!D4069)
A10: Intangibles | B10: =ABS('EF'!D7118) | F10: Otros pasivos | G10: =ABS('EF'!D14157) | J10: Gastos No Op | K10: =ABS('ER'!D4776)
